pc4-linux@pc4-linux:~/Pobrane$ sudo python3 symulacja_scada.py 
Traceback (most recent call last):
  File "<string>", line 1, in <module>
  File "/home/pc4-linux/Pobrane/symulacja_scada.py", line 82, in modbus_client
    client.write_register(1, value)
  File "/usr/local/lib/python3.8/dist-packages/pymodbus/client/common.py", line 92, in write_register
    return self.execute(request)
  File "/usr/local/lib/python3.8/dist-packages/pymodbus/client/sync.py", line 108, in execute
    raise ConnectionException("Failed to connect[%s]" % (self.__str__()))
pymodbus.exceptions.ConnectionException: Modbus Error: [Connection] Failed to connect[ModbusTcpClient(192.168.81.10:502)]
b' TCP : Network is unreachable'
Traceback (most recent call last):
  File "<string>", line 1, in <module>
  File "/home/pc4-linux/Pobrane/symulacja_scada.py", line 101, in s7_client
    client.connect('192.168.81.10', 0, 1, 102)
  File "/usr/local/lib/python3.8/dist-packages/snap7/client/__init__.py", line 24, in f
    check_error(code, context="client")
  File "/usr/local/lib/python3.8/dist-packages/snap7/common.py", line 89, in check_error
    raise RuntimeError(error)
RuntimeError: b' TCP : Network is unreachable'
